Workbook

Sheet Dashboard
B2: Budget & Commitments Dashboard | N2: CVR Month: May, 2026
B6: Total EAC | D6: Cost to Date | F6: Remaining | H6: Actuals | J6: Accrued | L6: Committed | N6: Over Budget | P6: Under Budget
B8: 1.1975881e+08 | D8: 96573487 | F8: 23185327 | H8: 21642147 | J8: 26722.21 | L8: 74904618 | N8: 0 | P8: 0
B54: Cost Code Summary
B55: Cost Code | C55: Item | H55: EAC | J55: CTD | L55: Remaining | N55: Actuals | P55: O/U
B56: 0-4004-01 | C56: 0-4004-01 Racking Materials | H56: 38327781 | J56: 46723601 | L56: -8395820 | N56: 10391392 | P56: ▲ Over
B57: 0-4004-05 | C57: 0-4004-05 PV Power Cable Materi | H57: 21422369 | J57: 20543723 | L57: 878646.07 | N57: 4497552.6 | P57: ✓ Under
B58: 0-4004-02 | C58: 0-4004-02 Inverter Materials | H58: 16780788 | J58: 21943590 | L58: -5162801.8 | N58: 4983660 | P58: ▲ Over
B59: 0-4004-08 | C59: 0-4004-08 PV Harness & LBDs | H59: 11679119 | J59: 0 | L59: 11679119 | N59: 0 | P59: ✓ Under
B60: 0-4013 | C60: 0-4013-Contingency | H60: 4883701.6 | J60: 0 | L60: 4883701.6 | N60: 0 | P60: ✓ Under
B61: 0-4109 | C61: 0-4109-Site Roadways | H61: 3249926 | J61: 1993005 | L61: 1256921.1 | N61: 0 | P61: ✓ Under
B62: 0-4024 | C62: 0-4024-Engineering | H62: 2800000 | J62: 1380959.6 | L62: 1419040.4 | N62: 1157305.6 | P62: ✓ Under
B63: 0-4008 | C63: 0-4008-Supplies | H63: 2425247.7 | J63: 179686.48 | L63: 2245561.2 | N63: 108788 | P63: ✓ Under
B64: 0-4004-07 | C64: 0-4004-07 Scada | H64: 1987506.3 | J64: 0 | L64: 1987506.3 | N64: 0 | P64: ✓ Under
B65: 0-4505 | C65: 0-4505-AC-MV Boring | H65: 1958336.6 | J65: 0 | L65: 1958336.6 | N65: 0 | P65: ✓ Under
B66: 0-4004-10 | C66: 0-4004-10 PV Electrical Materia | H66: 1936306 | J66: 36466.4 | L66: 1899839.6 | N66: 34328.11 | P66: ✓ Under
B67: 0-4010 | C67: 0-4010-FOG | H67: 1835125.6 | J67: -20637.25 | L67: 1855762.9 | N67: 42925.37 | P67: ✓ Under
... B124: 0-4xxy | C124: Opps | H124: -2420810.6 | J124: 0 | L124: -2420810.6 | N124: 0 | P124: ▲ Over

Sheet Category Table
A1: CVR Month: | B1: May, 2026 | C1: =SUBTOTAL(9,C4:C370) | D1: =SUBTOTAL(9,D4:D370) | E1: =SUBTOTAL(9,E4:E370) | F1: =SUBTOTAL(9,F4:F370) | G1: =SUBTOTAL(9,G4:G370) | H1: =SUBTOTAL(9,H4:H370) | I1: =SUBTOTAL(9,I4:I370) | J1: =SUBTOTAL(9,J4:J370) | ... AO1: =SUBTOTAL(9,AO4:AO370) | AP1: =IF(AM1>0, "Under",IF(AM1<0,"Over","")) | AQ1: =IF(AN1>0, "Under",IF(AN1<0,"Over","")) | AR1: =IF(AO1>0, "Under",IF(AO1<0,"Over",""))
C2: SU | D2: OC | E2: MA | F2: SU | G2: OC | H2: MA | I2: SU | J2: OC | K2: MA | L2: SU | M2: OC | N2: MA | O2: SU | P2: OC | Q2: MA | R2: SU | S2: OC | T2: MA | U2: SU | V2: OC | W2: MA | X2: SU | Y2: OC | Z2: MA | AA2: SU | AB2: OC | AC2: MA | AD2: SU | AE2: OC | AF2: MA | AG2: SU | AH2: OC | AI2: MA | AM2: SU | AN2: OC | AO2: MA | AP2: SU | AQ2: OC | AR2: MA
A3: Cost Code | B3: Item | C3: Subcontracts CVR Actual Cost | D3: Supplies CVR Actual Cost | E3: Material CVR Actual Cost | F3: Subcontracts CVR FC | G3: Supplies CVR FC | H3: Material CVR FC | I3: Subcontracts CVR Accruals | J3: Supplies CVR Accruals | K3: Material CVR Accruals | L3: Subcontracts CVR Out PO's | M3: Supplies CVR Out PO's | N3: Material CVR Out PO's | O3: Subcontracts CVR EAC | P3: Supplies CVR EAC | Q3: Material CVR EAC | R3: Subcontracts PO Log Amount | S3: Supplies PO Log Amount | T3: Material PO Log Amount | U3: Subcontracts Accrued Costs | V3: Supplies Accrued Costs | W3: Material Accrued Costs | X3: Subcontracts Comms Actuals | Y3: Supplies Comms Actuals | Z3: Material Comms Actuals | AA3: Subcontracts Committed | AB3: Supplies Committed | AC3: Material Committed | AD3: Subcontracts Total Comms JTD Cost | AE3: Supplies Total Comms JTD Cost | AF3: Material Total Comms JTD Cost | AG3: Subcontracts CTD | AH3: Supplies CTD | AI3: Material CTD | AJ3: Subcontracts Manual Adjustment | AK3: Supplies Manual Adjustment | AL3: Material Manual Adjustment | AM3: Subcontracts Rem EAC | AN3: Supplies Rem EAC | AO3: Material Rem EAC | AP3: Subcontracts Over/Under | AQ3: Supplies Over/Under | AR3: Material Over/Under
A4: 0-4000 | B4: 0-4000-Mobilization | C4: 0 | D4: 38865 | E4: 0 | F4: 178048.73 | G4: 0 | H4: 0 | I4: 0 | J4: 0 | K4: 0 | L4: 0 | M4: 0 | N4: 0 | O4: =L4+I4+F4+C4 | P4: =M4+J4+G4+D4 | Q4: =N4+K4+H4+E4 | R4: =SUMIFS('PO Log'!$E:$E,'PO Log'!$D:$D,'Category Table'!R$2,'PO Log'!$C:$C,'Category Table'!$A4) | S4: =SUMIFS('PO Log'!$E:$E,'PO Log'!$D:$D,'Category Table'!S$2,'PO Log'!$C:$C,'Category Table'!$A4) | T4: =SUMIFS('PO Log'!$E:$E,'PO Log'!$D:$D,'Category Table'!T$2,'PO Log'!$C:$C,'Category Table'!$A4) | U4: =SUMIFS('Committments Dump'!$Q:$Q,'Committments Dump'!$C:$C,'Category Table'!U$2,'Committments Dump'!$B:$B,'Category Table'!$A4) | V4: =SUMIFS('Committments Dump'!$Q:$Q,'Committments Dump'!$C:$C,'Category Table'!V$2,'Committments Dump'!$B:$B,'Category Table'!$A4) | W4: =SUMIFS('Committments Dump'!$Q:$Q,'Committments Dump'!$C:$C,'Category Table'!W$2,'Committments Dump'!$B:$B,'Category Table'!$A4) | X4: =SUMIFS('Committments Dump'!$R:$R,'Committments Dump'!$C:$C,'Category Table'!X$2,'Committments Dump'!$B:$B,'Category Table'!$A4) | Y4: =SUMIFS('Committments Dump'!$R:$R,'Committments Dump'!$C:$C,'Category Table'!Y$2,'Committments Dump'!$B:$B,'Category Table'!$A4) | Z4: =SUMIFS('Committments Dump'!$R:$R,'Committments Dump'!$C:$C,'Category Table'!Z$2,'Committments Dump'!$B:$B,'Category Table'!$A4) | AA4: =SUMIFS('Committments Dump'!$S:$S,'Committments Dump'!$C:$C,'Category Table'!AA$2,'Committments Dump'!$B:$B,'Category Table'!$A4) | AB4: =SUMIFS('Committments Dump'!$S:$S,'Committments Dump'!$C:$C,'Category Table'!AB$2,'Committments Dump'!$B:$B,'Category Table'!$A4) | AC4: =SUMIFS('Committments Dump'!$S:$S,'Committments Dump'!$C:$C,'Category Table'!AC$2,'Committments Dump'!$B:$B,'Category Table'!$A4) | AD4: =U4+X4+AA4 | AE4: =V4+Y4+AB4 | AF4: =W4+Z4+AC4 | AG4: =R4+AD4 | AH4: =S4+AE4 | AI4: =T4+AF4 | AM4: =(O4-AG4)+AJ4 | AN4: =(P4-AH4)+AK4 | AO4: =(Q4-AI4)+AL4 | AP4: =IF(AM4>0, "Under",IF(AM4<0,"Over","")) | AQ4: =IF(AN4>0, "Under",IF(AN4<0,"Over","")) | AR4: =IF(AO4>0, "Under",IF(AO4<0,"Over",""))
A5: 0-4001 | B5: 0-4001-Demobilization | C5: 0 | D5: 2350 | E5: 0 | F5: 220300.84 | G5: 0 | H5: 0 | I5: 0 | J5: 0 | K5: 0 | L5: 0 | M5: 0 | N5: 0 | O5: =L5+I5+F5+C5 | P5: =M5+J5+G5+D5 | Q5: =N5+K5+H5+E5 | R5: =SUMIFS('PO Log'!$E:$E,'PO Log'!$D:$D,'Category Table'!R$2,'PO Log'!$C:$C,'Category Table'!$A5) | S5: =SUMIFS('PO Log'!$E:$E,'PO Log'!$D:$D,'Category Table'!S$2,'PO Log'!$C:$C,'Category Table'!$A5) | T5: =SUMIFS('PO Log'!$E:$E,'PO Log'!$D:$D,'Category Table'!T$2,'PO Log'!$C:$C,'Category Table'!$A5) | U5: =SUMIFS('Committments Dump'!$Q:$Q,'Committments Dump'!$C:$C,'Category Table'!U$2,'Committments Dump'!$B:$B,'Category Table'!$A5) | V5: =SUMIFS('Committments Dump'!$Q:$Q,'Committments Dump'!$C:$C,'Category Table'!V$2,'Committments Dump'!$B:$B,'Category Table'!$A5) | W5: =SUMIFS('Committments Dump'!$Q:$Q,'Committments Dump'!$C:$C,'Category Table'!W$2,'Committments Dump'!$B:$B,'Category Table'!$A5) | X5: =SUMIFS('Committments Dump'!$R:$R,'Committments Dump'!$C:$C,'Category Table'!X$2,'Committments Dump'!$B:$B,'Category Table'!$A5) | Y5: =SUMIFS('Committments Dump'!$R:$R,'Committments Dump'!$C:$C,'Category Table'!Y$2,'Committments Dump'!$B:$B,'Category Table'!$A5) | Z5: =SUMIFS('Committments Dump'!$R:$R,'Committments Dump'!$C:$C,'Category Table'!Z$2,'Committments Dump'!$B:$B,'Category Table'!$A5) | AA5: =SUMIFS('Committments Dump'!$S:$S,'Committments Dump'!$C:$C,'Category Table'!AA$2,'Committments Dump'!$B:$B,'Category Table'!$A5) | AB5: =SUMIFS('Committments Dump'!$S:$S,'Committments Dump'!$C:$C,'Category Table'!AB$2,'Committments Dump'!$B:$B,'Category Table'!$A5) | AC5: =SUMIFS('Committments Dump'!$S:$S,'Committments Dump'!$C:$C,'Category Table'!AC$2,'Committments Dump'!$B:$B,'Category Table'!$A5) | AD5: =U5+X5+AA5 | AE5: =V5+Y5+AB5 | AF5: =W5+Z5+AC5 | AG5: =R5+AD5 | AH5: =S5+AE5 | AI5: =T5+AF5 | AM5: =(O5-AG5)+AJ5 | AN5: =(P5-AH5)+AK5 | AO5: =(Q5-AI5)+AL5 | AP5: =IF(AM5>0, "Under",IF(AM5<0,"Over","")) | AQ5: =IF(AN5>0, "Under",IF(AN5<0,"Over","")) | AR5: =IF(AO5>0, "Under",IF(AO5<0,"Over",""))
A6: 0-4004-01 | B6: 0-4004-01 Racking Materials | C6: 0 | D6: 1035502.4 | E6: 9355889.1 | H6: -8395820 | I6: 0 | J6: 0 | K6: 0 | L6: 0 | M6: 11408138 | N6: 24924071 | O6: =L6+I6+F6+C6 | P6: =M6+J6+G6+D6 | Q6: =N6+K6+H6+E6 | R6: =SUMIFS('PO Log'!$E:$E,'PO Log'!$D:$D,'Category Table'!R$2,'PO Log'!$C:$C,'Category Table'!$A6) | S6: =SUMIFS('PO Log'!$E:$E,'PO Log'!$D:$D,'Category Table'!S$2,'PO Log'!$C:$C,'Category Table'!$A6) | T6: =SUMIFS('PO Log'!$E:$E,'PO Log'!$D:$D,'Category Table'!T$2,'PO Log'!$C:$C,'Category Table'!$A6) | U6: =SUMIFS('Committments Dump'!$Q:$Q,'Committments Dump'!$C:$C,'Category Table'!U$2,'Committments Dump'!$B:$B,'Category Table'!$A6) | V6: =SUMIFS('Committments Dump'!$Q:$Q,'Committments Dump'!$C:$C,'Category Table'!V$2,'Committments Dump'!$B:$B,'Category Table'!$A6) | W6: =SUMIFS('Committments Dump'!$Q:$Q,'Committments Dump'!$C:$C,'Category Table'!W$2,'Committments Dump'!$B:$B,'Category Table'!$A6) | X6: =SUMIFS('Committments Dump'!$R:$R,'Committments Dump'!$C:$C,'Category Table'!X$2,'Committments Dump'!$B:$B,'Category Table'!$A6) | Y6: =SUMIFS('Committments Dump'!$R:$R,'Committments Dump'!$C:$C,'Category Table'!Y$2,'Committments Dump'!$B:$B,'Category Table'!$A6) | Z6: =SUMIFS('Committments Dump'!$R:$R,'Committments Dump'!$C:$C,'Category Table'!Z$2,'Committments Dump'!$B:$B,'Category Table'!$A6) | AA6: =SUMIFS('Committments Dump'!$S:$S,'Committments Dump'!$C:$C,'Category Table'!AA$2,'Committments Dump'!$B:$B,'Category Table'!$A6) | AB6: =SUMIFS('Committments Dump'!$S:$S,'Committments Dump'!$C:$C,'Category Table'!AB$2,'Committments Dump'!$B:$B,'Category Table'!$A6) | AC6: =SUMIFS('Committments Dump'!$S:$S,'Committments Dump'!$C:$C,'Category Table'!AC$2,'Committments Dump'!$B:$B,'Category Table'!$A6) | AD6: =U6+X6+AA6 | AE6: =V6+Y6+AB6 | AF6: =W6+Z6+AC6 | AG6: =R6+AD6 | AH6: =S6+AE6 | AI6: =T6+AF6 | AM6: =(O6-AG6)+AJ6 | AN6: =(P6-AH6)+AK6 | AO6: =(Q6-AI6)+AL6 | AP6: =IF(AM6>0, "Under",IF(AM6<0,"Over","")) | AQ6: =IF(AN6>0, "Under",IF(AN6<0,"Over","")) | AR6: =IF(AO6>0, "Under",IF(AO6<0,"Over",""))
A7: 0-4004-02 | B7: 0-4004-02 Inverter Materials | C7: 0 | D7: 0 | E7: 4983660 | F7: -350000 | H7: -4812801.8 | I7: 0 | J7: 0 | K7: 0 | L7: 0 | M7: 0 | N7: 16959930 | O7: =L7+I7+F7+C7 | P7: =M7+J7+G7+D7 | Q7: =N7+K7+H7+E7 | R7: =SUMIFS('PO Log'!$E:$E,'PO Log'!$D:$D,'Category Table'!R$2,'PO Log'!$C:$C,'Category Table'!$A7) | S7: =SUMIFS('PO Log'!$E:$E,'PO Log'!$D:$D,'Category Table'!S$2,'PO Log'!$C:$C,'Category Table'!$A7) | T7: =SUMIFS('PO Log'!$E:$E,'PO Log'!$D:$D,'Category Table'!T$2,'PO Log'!$C:$C,'Category Table'!$A7) | U7: =SUMIFS('Committments Dump'!$Q:$Q,'Committments Dump'!$C:$C,'Category Table'!U$2,'Committments Dump'!$B:$B,'Category Table'!$A7) | V7: =SUMIFS('Committments Dump'!$Q:$Q,'Committments Dump'!$C:$C,'Category Table'!V$2,'Committments Dump'!$B:$B,'Category Table'!$A7) | W7: =SUMIFS('Committments Dump'!$Q:$Q,'Committments Dump'!$C:$C,'Category Table'!W$2,'Committments Dump'!$B:$B,'Category Table'!$A7) | X7: =SUMIFS('Committments Dump'!$R:$R,'Committments Dump'!$C:$C,'Category Table'!X$2,'Committments Dump'!$B:$B,'Category Table'!$A7) | Y7: =SUMIFS('Committments Dump'!$R:$R,'Committments Dump'!$C:$C,'Category Table'!Y$2,'Committments Dump'!$B:$B,'Category Table'!$A7) | Z7: =SUMIFS('Committments Dump'!$R:$R,'Committments Dump'!$C:$C,'Category Table'!Z$2,'Committments Dump'!$B:$B,'Category Table'!$A7) | AA7: =SUMIFS('Committments Dump'!$S:$S,'Committments Dump'!$C:$C,'Category Table'!AA$2,'Committments Dump'!$B:$B,'Category Table'!$A7) | AB7: =SUMIFS('Committments Dump'!$S:$S,'Committments Dump'!$C:$C,'Category Table'!AB$2,'Committments Dump'!$B:$B,'Category Table'!$A7) | AC7: =SUMIFS('Committments Dump'!$S:$S,'Committments Dump'!$C:$C,'Category Table'!AC$2,'Committments Dump'!$B:$B,'Category Table'!$A7) | AD7: =U7+X7+AA7 | AE7: =V7+Y7+AB7 | AF7: =W7+Z7+AC7 | AG7: =R7+AD7 | AH7: =S7+AE7 | AI7: =T7+AF7 | AM7: =(O7-AG7)+AJ7 | AN7: =(P7-AH7)+AK7 | AO7: =(Q7-AI7)+AL7 | AP7: =IF(AM7>0, "Under",IF(AM7<0,"Over","")) | AQ7: =IF(AN7>0, "Under",IF(AN7<0,"Over","")) | AR7: =IF(AO7>0, "Under",IF(AO7<0,"Over",""))
A8: 0-4004-04 | B8: 0-4004-04 HV Breakers | C8: 0 | D8: 0 | E8: 0 | F8: 0 | G8: 0 | H8: 0 | I8: 0 | J8: 0 | K8: 0 | L8: 0 | M8: 0 | N8: 0 | O8: =L8+I8+F8+C8 | P8: =M8+J8+G8+D8 | Q8: =N8+K8+H8+E8 | R8: =SUMIFS('PO Log'!$E:$E,'PO Log'!$D:$D,'Category Table'!R$2,'PO Log'!$C:$C,'Category Table'!$A8) | S8: =SUMIFS('PO Log'!$E:$E,'PO Log'!$D:$D,'Category Table'!S$2,'PO Log'!$C:$C,'Category Table'!$A8) | T8: =SUMIFS('PO Log'!$E:$E,'PO Log'!$D:$D,'Category Table'!T$2,'PO Log'!$C:$C,'Category Table'!$A8) | U8: =SUMIFS('Committments Dump'!$Q:$Q,'Committments Dump'!$C:$C,'Category Table'!U$2,'Committments Dump'!$B:$B,'Category Table'!$A8) | V8: =SUMIFS('Committments Dump'!$Q:$Q,'Committments Dump'!$C:$C,'Category Table'!V$2,'Committments Dump'!$B:$B,'Category Table'!$A8) | W8: =SUMIFS('Committments Dump'!$Q:$Q,'Committments Dump'!$C:$C,'Category Table'!W$2,'Committments Dump'!$B:$B,'Category Table'!$A8) | X8: =SUMIFS('Committments Dump'!$R:$R,'Committments Dump'!$C:$C,'Category Table'!X$2,'Committments Dump'!$B:$B,'Category Table'!$A8) | Y8: =SUMIFS('Committments Dump'!$R:$R,'Committments Dump'!$C:$C,'Category Table'!Y$2,'Committments Dump'!$B:$B,'Category Table'!$A8) | Z8: =SUMIFS('Committments Dump'!$R:$R,'Committments Dump'!$C:$C,'Category Table'!Z$2,'Committments Dump'!$B:$B,'Category Table'!$A8) | AA8: =SUMIFS('Committments Dump'!$S:$S,'Committments Dump'!$C:$C,'Category Table'!AA$2,'Committments Dump'!$B:$B,'Category Table'!$A8) | AB8: =SUMIFS('Committments Dump'!$S:$S,'Committments Dump'!$C:$C,'Category Table'!AB$2,'Committments Dump'!$B:$B,'Category Table'!$A8) | AC8: =SUMIFS('Committments Dump'!$S:$S,'Committments Dump'!$C:$C,'Category Table'!AC$2,'Committments Dump'!$B:$B,'Category Table'!$A8) | AD8: =U8+X8+AA8 | AE8: =V8+Y8+AB8 | AF8: =W8+Z8+AC8 | AG8: =R8+AD8 | AH8: =S8+AE8 | AI8: =T8+AF8 | AM8: =(O8-AG8)+AJ8 | AN8: =(P8-AH8)+AK8 | AO8: =(Q8-AI8)+AL8 | AP8: =IF(AM8>0, "Under",IF(AM8<0,"Over","")) | AQ8: =IF(AN8>0, "Under",IF(AN8<0,"Over","")) | AR8: =IF(AO8>0, "Under",IF(AO8<0,"Over",""))
A9: 0-4004-05 | B9: 0-4004-05 PV Power Cable Materi | C9: 0 | D9: 0 | E9: 4497552.6 | F9: 1264434 | G9: -385787.98 | I9: 0 | J9: 0 | K9: 21748.27 | L9: 0 | M9: 1033828.5 | N9: 14990594 | O9: =L9+I9+F9+C9 | P9: =M9+J9+G9+D9 | Q9: =N9+K9+H9+E9 | R9: =SUMIFS('PO Log'!$E:$E,'PO Log'!$D:$D,'Category Table'!R$2,'PO Log'!$C:$C,'Category Table'!$A9) | S9: =SUMIFS('PO Log'!$E:$E,'PO Log'!$D:$D,'Category Table'!S$2,'PO Log'!$C:$C,'Category Table'!$A9) | T9: =SUMIFS('PO Log'!$E:$E,'PO Log'!$D:$D,'Category Table'!T$2,'PO Log'!$C:$C,'Category Table'!$A9) | U9: =SUMIFS('Committments Dump'!$Q:$Q,'Committments Dump'!$C:$C,'Category Table'!U$2,'Committments Dump'!$B:$B,'Category Table'!$A9) | V9: =SUMIFS('Committments Dump'!$Q:$Q,'Committments Dump'!$C:$C,'Category Table'!V$2,'Committments Dump'!$B:$B,'Category Table'!$A9) | W9: =SUMIFS('Committments Dump'!$Q:$Q,'Committments Dump'!$C:$C,'Category Table'!W$2,'Committments Dump'!$B:$B,'Category Table'!$A9) | X9: =SUMIFS('Committments Dump'!$R:$R,'Committments Dump'!$C:$C,'Category Table'!X$2,'Committments Dump'!$B:$B,'Category Table'!$A9) | Y9: =SUMIFS('Committments Dump'!$R:$R,'Committments Dump'!$C:$C,'Category Table'!Y$2,'Committments Dump'!$B:$B,'Category Table'!$A9) | Z9: =SUMIFS('Committments Dump'!$R:$R,'Committments Dump'!$C:$C,'Category Table'!Z$2,'Committments Dump'!$B:$B,'Category Table'!$A9) | AA9: =SUMIFS('Committments Dump'!$S:$S,'Committments Dump'!$C:$C,'Category Table'!AA$2,'Committments Dump'!$B:$B,'Category Table'!$A9) | AB9: =SUMIFS('Committments Dump'!$S:$S,'Committments Dump'!$C:$C,'Category Table'!AB$2,'Committments Dump'!$B:$B,'Category Table'!$A9) | AC9: =SUMIFS('Committments Dump'!$S:$S,'Committments Dump'!$C:$C,'Category Table'!AC$2,'Committments Dump'!$B:$B,'Category Table'!$A9) | AD9: =U9+X9+AA9 | AE9: =V9+Y9+AB9 | AF9: =W9+Z9+AC9 | AG9: =R9+AD9 | AH9: =S9+AE9 | AI9: =T9+AF9 | AM9: =(O9-AG9)+AJ9 | AN9: =(P9-AH9)+AK9 | AO9: =(Q9-AI9)+AL9 | AP9: =IF(AM9>0, "Under",IF(AM9<0,"Over","")) | AQ9: =IF(AN9>0, "Under",IF(AN9<0,"Over","")) | AR9: =IF(AO9>0, "Under",IF(AO9<0,"Over",""))
A10: 0-4004-06 | B10: 0-4004-06 Cable Management | C10: 0 | D10: 0 | E10: 0 | F10: 0 | G10: 0 | H10: 1624884 | I10: 0 | J10: 0 | K10: 0 | L10: 0 | M10: 0 | N10: 0 | O10: =L10+I10+F10+C10 | P10: =M10+J10+G10+D10 | Q10: =N10+K10+H10+E10 | R10: =SUMIFS('PO Log'!$E:$E,'PO Log'!$D:$D,'Category Table'!R$2,'PO Log'!$C:$C,'Category Table'!$A10) | S10: =SUMIFS('PO Log'!$E:$E,'PO Log'!$D:$D,'Category Table'!S$2,'PO Log'!$C:$C,'Category Table'!$A10) | T10: =SUMIFS('PO Log'!$E:$E,'PO Log'!$D:$D,'Category Table'!T$2,'PO Log'!$C:$C,'Category Table'!$A10) | U10: =SUMIFS('Committments Dump'!$Q:$Q,'Committments Dump'!$C:$C,'Category Table'!U$2,'Committments Dump'!$B:$B,'Category Table'!$A10) | V10: =SUMIFS('Committments Dump'!$Q:$Q,'Committments Dump'!$C:$C,'Category Table'!V$2,'Committments Dump'!$B:$B,'Category Table'!$A10) | W10: =SUMIFS('Committments Dump'!$Q:$Q,'Committments Dump'!$C:$C,'Category Table'!W$2,'Committments Dump'!$B:$B,'Category Table'!$A10) | X10: =SUMIFS('Committments Dump'!$R:$R,'Committments Dump'!$C:$C,'Category Table'!X$2,'Committments Dump'!$B:$B,'Category Table'!$A10) | Y10: =SUMIFS('Committments Dump'!$R:$R,'Committments Dump'!$C:$C,'Category Table'!Y$2,'Committments Dump'!$B:$B,'Category Table'!$A10) | Z10: =SUMIFS('Committments Dump'!$R:$R,'Committments Dump'!$C:$C,'Category Table'!Z$2,'Committments Dump'!$B:$B,'Category Table'!$A10) | AA10: =SUMIFS('Committments Dump'!$S:$S,'Committments Dump'!$C:$C,'Category Table'!AA$2,'Committments Dump'!$B:$B,'Category Table'!$A10) | AB10: =SUMIFS('Committments Dump'!$S:$S,'Committments Dump'!$C:$C,'Category Table'!AB$2,'Committments Dump'!$B:$B,'Category Table'!$A10) | AC10: =SUMIFS('Committments Dump'!$S:$S,'Committments Dump'!$C:$C,'Category Table'!AC$2,'Committments Dump'!$B:$B,'Category Table'!$A10) | AD10: =U10+X10+AA10 | AE10: =V10+Y10+AB10 | AF10: =W10+Z10+AC10 | AG10: =R10+AD10 | AH10: =S10+AE10 | AI10: =T10+AF10 | AM10: =(O10-AG10)+AJ10 | AN10: =(P10-AH10)+AK10 | AO10: =(Q10-AI10)+AL10 | AP10: =IF(AM10>0, "Under",IF(AM10<0,"Over","")) | AQ10: =IF(AN10>0, "Under",IF(AN10<0,"Over","")) | AR10: =IF(AO10>0, "Under",IF(AO10<0,"Over",""))
A11: 0-4004-07 | B11: 0-4004-07 Scada | C11: 0 | D11: 0 | E11: 0 | F11: 138740 | G11: 0 | H11: 1848766.3 | I11: 0 | J11: 0 | K11: 0 | L11: 0 | M11: 0 | N11: 0 | O11: =L11+I11+F11+C11 | P11: =M11+J11+G11+D11 | Q11: =N11+K11+H11+E11 | R11: =SUMIFS('PO Log'!$E:$E,'PO Log'!$D:$D,'Category Table'!R$2,'PO Log'!$C:$C,'Category Table'!$A11) | S11: =SUMIFS('PO Log'!$E:$E,'PO Log'!$D:$D,'Category Table'!S$2,'PO Log'!$C:$C,'Category Table'!$A11) | T11: =SUMIFS('PO Log'!$E:$E,'PO Log'!$D:$D,'Category Table'!T$2,'PO Log'!$C:$C,'Category Table'!$A11) | U11: =SUMIFS('Committments Dump'!$Q:$Q,'Committments Dump'!$C:$C,'Category Table'!U$2,'Committments Dump'!$B:$B,'Category Table'!$A11) | V11: =SUMIFS('Committments Dump'!$Q:$Q,'Committments Dump'!$C:$C,'Category Table'!V$2,'Committments Dump'!$B:$B,'Category Table'!$A11) | W11: =SUMIFS('Committments Dump'!$Q:$Q,'Committments Dump'!$C:$C,'Category Table'!W$2,'Committments Dump'!$B:$B,'Category Table'!$A11) | X11: =SUMIFS('Committments Dump'!$R:$R,'Committments Dump'!$C:$C,'Category Table'!X$2,'Committments Dump'!$B:$B,'Category Table'!$A11) | Y11: =SUMIFS('Committments Dump'!$R:$R,'Committments Dump'!$C:$C,'Category Table'!Y$2,'Committments Dump'!$B:$B,'Category Table'!$A11) | Z11: =SUMIFS('Committments Dump'!$R:$R,'Committments Dump'!$C:$C,'Category Table'!Z$2,'Committments Dump'!$B:$B,'Category Table'!$A11) | AA11: =SUMIFS('Committments Dump'!$S:$S,'Committments Dump'!$C:$C,'Category Table'!AA$2,'Committments Dump'!$B:$B,'Category Table'!$A11) | AB11: =SUMIFS('Committments Dump'!$S:$S,'Committments Dump'!$C:$C,'Category Table'!AB$2,'Committments Dump'!$B:$B,'Category Table'!$A11) | AC11: =SUMIFS('Committments Dump'!$S:$S,'Committments Dump'!$C:$C,'Category Table'!AC$2,'Committments Dump'!$B:$B,'Category Table'!$A11) | AD11: =U11+X11+AA11 | AE11: =V11+Y11+AB11 | AF11: =W11+Z11+AC11 | AG11: =R11+AD11 | AH11: =S11+AE11 | AI11: =T11+AF11 | AM11: =(O11-AG11)+AJ11 | AN11: =(P11-AH11)+AK11 | AO11: =(Q11-AI11)+AL11 | AP11: =IF(AM11>0, "Under",IF(AM11<0,"Over","")) | AQ11: =IF(AN11>0, "Under",IF(AN11<0,"Over","")) | AR11: =IF(AO11>0, "Under",IF(AO11<0,"Over",""))
A12: 0-4004-08 | B12: 0-4004-08 PV Harness & LBDs | C12: 0 | D12: 0 | E12: 0 | F12: 0 | G12: 0 | H12: 11679119 | I12: 0 | J12: 0 | K12: 0 | L12: 0 | M12: 0 | N12: 0 | O12: =L12+I12+F12+C12 | P12: =M12+J12+G12+D12 | Q12: =N12+K12+H12+E12 | R12: =SUMIFS('PO Log'!$E:$E,'PO Log'!$D:$D,'Category Table'!R$2,'PO Log'!$C:$C,'Category Table'!$A12) | S12: =SUMIFS('PO Log'!$E:$E,'PO Log'!$D:$D,'Category Table'!S$2,'PO Log'!$C:$C,'Category Table'!$A12) | T12: =SUMIFS('PO Log'!$E:$E,'PO Log'!$D:$D,'Category Table'!T$2,'PO Log'!$C:$C,'Category Table'!$A12) | U12: =SUMIFS('Committments Dump'!$Q:$Q,'Committments Dump'!$C:$C,'Category Table'!U$2,'Committments Dump'!$B:$B,'Category Table'!$A12) | V12: =SUMIFS('Committments Dump'!$Q:$Q,'Committments Dump'!$C:$C,'Category Table'!V$2,'Committments Dump'!$B:$B,'Category Table'!$A12) | W12: =SUMIFS('Committments Dump'!$Q:$Q,'Committments Dump'!$C:$C,'Category Table'!W$2,'Committments Dump'!$B:$B,'Category Table'!$A12) | X12: =SUMIFS('Committments Dump'!$R:$R,'Committments Dump'!$C:$C,'Category Table'!X$2,'Committments Dump'!$B:$B,'Category Table'!$A12) | Y12: =SUMIFS('Committments Dump'!$R:$R,'Committments Dump'!$C:$C,'Category Table'!Y$2,'Committments Dump'!$B:$B,'Category Table'!$A12) | Z12: =SUMIFS('Committments Dump'!$R:$R,'Committments Dump'!$C:$C,'Category Table'!Z$2,'Committments Dump'!$B:$B,'Category Table'!$A12) | AA12: =SUMIFS('Committments Dump'!$S:$S,'Committments Dump'!$C:$C,'Category Table'!AA$2,'Committments Dump'!$B:$B,'Category Table'!$A12) | AB12: =SUMIFS('Committments Dump'!$S:$S,'Committments Dump'!$C:$C,'Category Table'!AB$2,'Committments Dump'!$B:$B,'Category Table'!$A12) | AC12: =SUMIFS('Committments Dump'!$S:$S,'Committments Dump'!$C:$C,'Category Table'!AC$2,'Committments Dump'!$B:$B,'Category Table'!$A12) | AD12: =U12+X12+AA12 | AE12: =V12+Y12+AB12 | AF12: =W12+Z12+AC12 | AG12: =R12+AD12 | AH12: =S12+AE12 | AI12: =T12+AF12 | AM12: =(O12-AG12)+AJ12 | AN12: =(P12-AH12)+AK12 | AO12: =(Q12-AI12)+AL12 | AP12: =IF(AM12>0, "Under",IF(AM12<0,"Over","")) | AQ12: =IF(AN12>0, "Under",IF(AN12<0,"Over","")) | AR12: =IF(AO12>0, "Under",IF(AO12<0,"Over",""))
A13: 0-4004-10 | B13: 0-4004-10 PV Electrical Materia | C13: 0 | D13: 123.43 | E13: 34204.68 | F13: 0 | G13: -132692.59 | H13: 2032532.2 | I13: 0 | J13: 10.4 | K13: 2127.89 | L13: 0 | M13: 0 | N13: 4.0927262e-12 | O13: =L13+I13+F13+C13 | P13: =M13+J13+G13+D13 | Q13: =N13+K13+H13+E13 | R13: =SUMIFS('PO Log'!$E:$E,'PO Log'!$D:$D,'Category Table'!R$2,'PO Log'!$C:$C,'Category Table'!$A13) | S13: =SUMIFS('PO Log'!$E:$E,'PO Log'!$D:$D,'Category Table'!S$2,'PO Log'!$C:$C,'Category Table'!$A13) | T13: =SUMIFS('PO Log'!$E:$E,'PO Log'!$D:$D,'Category Table'!T$2,'PO Log'!$C:$C,'Category Table'!$A13) | U13: =SUMIFS('Committments Dump'!$Q:$Q,'Committments Dump'!$C:$C,'Category Table'!U$2,'Committments Dump'!$B:$B,'Category Table'!$A13) | V13: =SUMIFS('Committments Dump'!$Q:$Q,'Committments Dump'!$C:$C,'Category Table'!V$2,'Committments Dump'!$B:$B,'Category Table'!$A13) | W13: =SUMIFS('Committments Dump'!$Q:$Q,'Committments Dump'!$C:$C,'Category Table'!W$2,'Committments Dump'!$B:$B,'Category Table'!$A13) | X13: =SUMIFS('Committments Dump'!$R:$R,'Committments Dump'!$C:$C,'Category Table'!X$2,'Committments Dump'!$B:$B,'Category Table'!$A13) | Y13: =SUMIFS('Committments Dump'!$R:$R,'Committments Dump'!$C:$C,'Category Table'!Y$2,'Committments Dump'!$B:$B,'Category Table'!$A13) | Z13: =SUMIFS('Committments Dump'!$R:$R,'Committments Dump'!$C:$C,'Category Table'!Z$2,'Committments Dump'!$B:$B,'Category Table'!$A13) | AA13: =SUMIFS('Committments Dump'!$S:$S,'Committments Dump'!$C:$C,'Category Table'!AA$2,'Committments Dump'!$B:$B,'Category Table'!$A13) | AB13: =SUMIFS('Committments Dump'!$S:$S,'Committments Dump'!$C:$C,'Category Table'!AB$2,'Committments Dump'!$B:$B,'Category Table'!$A13) | AC13: =SUMIFS('Committments Dump'!$S:$S,'Committments Dump'!$C:$C,'Category Table'!AC$2,'Committments Dump'!$B:$B,'Category Table'!$A13) | AD13: =U13+X13+AA13 | AE13: =V13+Y13+AB13 | AF13: =W13+Z13+AC13 | AG13: =R13+AD13 | AH13: =S13+AE13 | AI13: =T13+AF13 | AM13: =(O13-AG13)+AJ13 | AN13: =(P13-AH13)+AK13 | AO13: =(Q13-AI13)+AL13 | AP13: =IF(AM13>0, "Under",IF(AM13<0,"Over","")) | AQ13: =IF(AN13>0, "Under",IF(AN13<0,"Over","")) | AR13: =IF(AO13>0, "Under",IF(AO13<0,"Over",""))
A14: 0-4004-12 | B14: 0-4004-12 Non Tracker Piles | C14: 0 | D14: 0 | E14: 0 | F14: 0 | G14: 0 | I14: 0 | J14: 0 | K14: 0 | L14: 0 | M14: 212948.61 | N14: 754485.45 | O14: =L14+I14+F14+C14 | P14: =M14+J14+G14+D14 | Q14: =N14+K14+H14+E14 | R14: =SUMIFS('PO Log'!$E:$E,'PO Log'!$D:$D,'Category Table'!R$2,'PO Log'!$C:$C,'Category Table'!$A14) | S14: =SUMIFS('PO Log'!$E:$E,'PO Log'!$D:$D,'Category Table'!S$2,'PO Log'!$C:$C,'Category Table'!$A14) | T14: =SUMIFS('PO Log'!$E:$E,'PO Log'!$D:$D,'Category Table'!T$2,'PO Log'!$C:$C,'Category Table'!$A14) | U14: =SUMIFS('Committments Dump'!$Q:$Q,'Committments Dump'!$C:$C,'Category Table'!U$2,'Committments Dump'!$B:$B,'Category Table'!$A14) | V14: =SUMIFS('Committments Dump'!$Q:$Q,'Committments Dump'!$C:$C,'Category Table'!V$2,'Committments Dump'!$B:$B,'Category Table'!$A14) | W14: =SUMIFS('Committments Dump'!$Q:$Q,'Committments Dump'!$C:$C,'Category Table'!W$2,'Committments Dump'!$B:$B,'Category Table'!$A14) | X14: =SUMIFS('Committments Dump'!$R:$R,'Committments Dump'!$C:$C,'Category Table'!X$2,'Committments Dump'!$B:$B,'Category Table'!$A14) | Y14: =SUMIFS('Committments Dump'!$R:$R,'Committments Dump'!$C:$C,'Category Table'!Y$2,'Committments Dump'!$B:$B,'Category Table'!$A14) | Z14: =SUMIFS('Committments Dump'!$R:$R,'Committments Dump'!$C:$C,'Category Table'!Z$2,'Committments Dump'!$B:$B,'Category Table'!$A14) | AA14: =SUMIFS('Committments Dump'!$S:$S,'Committments Dump'!$C:$C,'Category Table'!AA$2,'Committments Dump'!$B:$B,'Category Table'!$A14) | AB14: =SUMIFS('Committments Dump'!$S:$S,'Committments Dump'!$C:$C,'Category Table'!AB$2,'Committments Dump'!$B:$B,'Category Table'!$A14) | AC14: =SUMIFS('Committments Dump'!$S:$S,'Committments Dump'!$C:$C,'Category Table'!AC$2,'Committments Dump'!$B:$B,'Category Table'!$A14) | AD14: =U14+X14+AA14 | AE14: =V14+Y14+AB14 | AF14: =W14+Z14+AC14 | AG14: =R14+AD14 | AH14: =S14+AE14 | AI14: =T14+AF14 | AM14: =(O14-AG14)+AJ14 | AN14: =(P14-AH14)+AK14 | AO14: =(Q14-AI14)+AL14 | AP14: =IF(AM14>0, "Under",IF(AM14<0,"Over","")) | AQ14: =IF(AN14>0, "Under",IF(AN14<0,"Over","")) | AR14: =IF(AO14>0, "Under",IF(AO14<0,"Over",""))
A15: 0-4004-13 | B15: 0-4004-13 CenterPoint's Breaker | C15: 0 | D15: 0 | E15: 0 | F15: 0 | G15: 0 | H15: -33000 | I15: 0 | J15: 0 | K15: 0 | L15: 0 | M15: 0 | N15: 333000 | O15: =L15+I15+F15+C15 | P15: =M15+J15+G15+D15 | Q15: =N15+K15+H15+E15 | R15: =SUMIFS('PO Log'!$E:$E,'PO Log'!$D:$D,'Category Table'!R$2,'PO Log'!$C:$C,'Category Table'!$A15) | S15: =SUMIFS('PO Log'!$E:$E,'PO Log'!$D:$D,'Category Table'!S$2,'PO Log'!$C:$C,'Category Table'!$A15) | T15: =SUMIFS('PO Log'!$E:$E,'PO Log'!$D:$D,'Category Table'!T$2,'PO Log'!$C:$C,'Category Table'!$A15) | U15: =SUMIFS('Committments Dump'!$Q:$Q,'Committments Dump'!$C:$C,'Category Table'!U$2,'Committments Dump'!$B:$B,'Category Table'!$A15) | V15: =SUMIFS('Committments Dump'!$Q:$Q,'Committments Dump'!$C:$C,'Category Table'!V$2,'Committments Dump'!$B:$B,'Category Table'!$A15) | W15: =SUMIFS('Committments Dump'!$Q:$Q,'Committments Dump'!$C:$C,'Category Table'!W$2,'Committments Dump'!$B:$B,'Category Table'!$A15) | X15: =SUMIFS('Committments Dump'!$R:$R,'Committments Dump'!$C:$C,'Category Table'!X$2,'Committments Dump'!$B:$B,'Category Table'!$A15) | Y15: =SUMIFS('Committments Dump'!$R:$R,'Committments Dump'!$C:$C,'Category Table'!Y$2,'Committments Dump'!$B:$B,'Category Table'!$A15) | Z15: =SUMIFS('Committments Dump'!$R:$R,'Committments Dump'!$C:$C,'Category Table'!Z$2,'Committments Dump'!$B:$B,'Category Table'!$A15) | AA15: =SUMIFS('Committments Dump'!$S:$S,'Committments Dump'!$C:$C,'Category Table'!AA$2,'Committments Dump'!$B:$B,'Category Table'!$A15) | AB15: =SUMIFS('Committments Dump'!$S:$S,'Committments Dump'!$C:$C,'Category Table'!AB$2,'Committments Dump'!$B:$B,'Category Table'!$A15) | AC15: =SUMIFS('Committments Dump'!$S:$S,'Committments Dump'!$C:$C,'Category Table'!AC$2,'Committments Dump'!$B:$B,'Category Table'!$A15) | AD15: =U15+X15+AA15 | AE15: =V15+Y15+AB15 | AF15: =W15+Z15+AC15 | AG15: =R15+AD15 | AH15: =S15+AE15 | AI15: =T15+AF15 | AM15: =(O15-AG15)+AJ15 | AN15: =(P15-AH15)+AK15 | AO15: =(Q15-AI15)+AL15 | AP15: =IF(AM15>0, "Under",IF(AM15<0,"Over","")) | AQ15: =IF(AN15>0, "Under",IF(AN15<0,"Over","")) | AR15: =IF(AO15>0, "Under",IF(AO15<0,"Over",""))
A16: 0-4005 | B16: 0-4005-FOE | C16: 0 | D16: 20433.51 | E16: 0 | F16: 0 | G16: 3435.3685 | H16: 0 | I16: 0 | J16: 0 | K16: 0 | L16: 0 | M16: 0 | N16: 0 | O16: =L16+I16+F16+C16 | P16: =M16+J16+G16+D16 | Q16: =N16+K16+H16+E16 | R16: =SUMIFS('PO Log'!$E:$E,'PO Log'!$D:$D,'Category Table'!R$2,'PO Log'!$C:$C,'Category Table'!$A16) | S16: =SUMIFS('PO Log'!$E:$E,'PO Log'!$D:$D,'Category Table'!S$2,'PO Log'!$C:$C,'Category Table'!$A16) | T16: =SUMIFS('PO Log'!$E:$E,'PO Log'!$D:$D,'Category Table'!T$2,'PO Log'!$C:$C,'Category Table'!$A16) | U16: =SUMIFS('Committments Dump'!$Q:$Q,'Committments Dump'!$C:$C,'Category Table'!U$2,'Committments Dump'!$B:$B,'Category Table'!$A16) | V16: =SUMIFS('Committments Dump'!$Q:$Q,'Committments Dump'!$C:$C,'Category Table'!V$2,'Committments Dump'!$B:$B,'Category Table'!$A16) | W16: =SUMIFS('Committments Dump'!$Q:$Q,'Committments Dump'!$C:$C,'Category Table'!W$2,'Committments Dump'!$B:$B,'Category Table'!$A16) | X16: =SUMIFS('Committments Dump'!$R:$R,'Committments Dump'!$C:$C,'Category Table'!X$2,'Committments Dump'!$B:$B,'Category Table'!$A16) | Y16: =SUMIFS('Committments Dump'!$R:$R,'Committments Dump'!$C:$C,'Category Table'!Y$2,'Committments Dump'!$B:$B,'Category Table'!$A16) | Z16: =SUMIFS('Committments Dump'!$R:$R,'Committments Dump'!$C:$C,'Category Table'!Z$2,'Committments Dump'!$B:$B,'Category Table'!$A16) | AA16: =SUMIFS('Committments Dump'!$S:$S,'Committments Dump'!$C:$C,'Category Table'!AA$2,'Committments Dump'!$B:$B,'Category Table'!$A16) | AB16: =SUMIFS('Committments Dump'!$S:$S,'Committments Dump'!$C:$C,'Category Table'!AB$2,'Committments Dump'!$B:$B,'Category Table'!$A16) | AC16: =SUMIFS('Committments Dump'!$S:$S,'Committments Dump'!$C:$C,'Category Table'!AC$2,'Committments Dump'!$B:$B,'Category Table'!$A16) | AD16: =U16+X16+AA16 | AE16: =V16+Y16+AB16 | AF16: =W16+Z16+AC16 | AG16: =R16+AD16 | AH16: =S16+AE16 | AI16: =T16+AF16 | AM16: =(O16-AG16)+AJ16 | AN16: =(P16-AH16)+AK16 | AO16: =(Q16-AI16)+AL16 | AP16: =IF(AM16>0, "Under",IF(AM16<0,"Over","")) | AQ16: =IF(AN16>0, "Under",IF(AN16<0,"Over","")) | AR16: =IF(AO16>0, "Under",IF(AO16<0,"Over",""))
A17: 0-4005-02 | B17: 0-4005-02 Commish FOE | C17: 0 | D17: 0 | E17: 0 | F17: 0 | G17: 0 | H17: 0 | I17: 0 | J17: 0 | K17: 0 | L17: 0 | M17: 0 | N17: 0 | O17: =L17+I17+F17+C17 | P17: =M17+J17+G17+D17 | Q17: =N17+K17+H17+E17 | R17: =SUMIFS('PO Log'!$E:$E,'PO Log'!$D:$D,'Category Table'!R$2,'PO Log'!$C:$C,'Category Table'!$A17) | S17: =SUMIFS('PO Log'!$E:$E,'PO Log'!$D:$D,'Category Table'!S$2,'PO Log'!$C:$C,'Category Table'!$A17) | T17: =SUMIFS('PO Log'!$E:$E,'PO Log'!$D:$D,'Category Table'!T$2,'PO Log'!$C:$C,'Category Table'!$A17) | U17: =SUMIFS('Committments Dump'!$Q:$Q,'Committments Dump'!$C:$C,'Category Table'!U$2,'Committments Dump'!$B:$B,'Category Table'!$A17) | V17: =SUMIFS('Committments Dump'!$Q:$Q,'Committments Dump'!$C:$C,'Category Table'!V$2,'Committments Dump'!$B:$B,'Category Table'!$A17) | W17: =SUMIFS('Committments Dump'!$Q:$Q,'Committments Dump'!$C:$C,'Category Table'!W$2,'Committments Dump'!$B:$B,'Category Table'!$A17) | X17: =SUMIFS('Committments Dump'!$R:$R,'Committments Dump'!$C:$C,'Category Table'!X$2,'Committments Dump'!$B:$B,'Category Table'!$A17) | Y17: =SUMIFS('Committments Dump'!$R:$R,'Committments Dump'!$C:$C,'Category Table'!Y$2,'Committments Dump'!$B:$B,'Category Table'!$A17) | Z17: =SUMIFS('Committments Dump'!$R:$R,'Committments Dump'!$C:$C,'Category Table'!Z$2,'Committments Dump'!$B:$B,'Category Table'!$A17) | AA17: =SUMIFS('Committments Dump'!$S:$S,'Committments Dump'!$C:$C,'Category Table'!AA$2,'Committments Dump'!$B:$B,'Category Table'!$A17) | AB17: =SUMIFS('Committments Dump'!$S:$S,'Committments Dump'!$C:$C,'Category Table'!AB$2,'Committments Dump'!$B:$B,'Category Table'!$A17) | AC17: =SUMIFS('Committments Dump'!$S:$S,'Committments Dump'!$C:$C,'Category Table'!AC$2,'Committments Dump'!$B:$B,'Category Table'!$A17) | AD17: =U17+X17+AA17 | AE17: =V17+Y17+AB17 | AF17: =W17+Z17+AC17 | AG17: =R17+AD17 | AH17: =S17+AE17 | AI17: =T17+AF17 | AM17: =(O17-AG17)+AJ17 | AN17: =(P17-AH17)+AK17 | AO17: =(Q17-AI17)+AL17 | AP17: =IF(AM17>0, "Under",IF(AM17<0,"Over","")) | AQ17: =IF(AN17>0, "Under",IF(AN17<0,"Over","")) | AR17: =IF(AO17>0, "Under",IF(AO17<0,"Over",""))
A18: 0-4006 | B18: 0-4006-Yard and Trailer | C18: 0 | D18: 35420.42 | E18: 0 | F18: 76535.447 | H18: 0 | I18: 0 | J18: 0 | K18: 0 | L18: 0 | M18: 277325.56 | N18: 0 | O18: =L18+I18+F18+C18 | P18: =M18+J18+G18+D18 | Q18: =N18+K18+H18+E18 | R18: =SUMIFS('PO Log'!$E:$E,'PO Log'!$D:$D,'Category Table'!R$2,'PO Log'!$C:$C,'Category Table'!$A18) | S18: =SUMIFS('PO Log'!$E:$E,'PO Log'!$D:$D,'Category Table'!S$2,'PO Log'!$C:$C,'Category Table'!$A18) | T18: =SUMIFS('PO Log'!$E:$E,'PO Log'!$D:$D,'Category Table'!T$2,'PO Log'!$C:$C,'Category Table'!$A18) | U18: =SUMIFS('Committments Dump'!$Q:$Q,'Committments Dump'!$C:$C,'Category Table'!U$2,'Committments Dump'!$B:$B,'Category Table'!$A18) | V18: =SUMIFS('Committments Dump'!$Q:$Q,'Committments Dump'!$C:$C,'Category Table'!V$2,'Committments Dump'!$B:$B,'Category Table'!$A18) | W18: =SUMIFS('Committments Dump'!$Q:$Q,'Committments Dump'!$C:$C,'Category Table'!W$2,'Committments Dump'!$B:$B,'Category Table'!$A18) | X18: =SUMIFS('Committments Dump'!$R:$R,'Committments Dump'!$C:$C,'Category Table'!X$2,'Committments Dump'!$B:$B,'Category Table'!$A18) | Y18: =SUMIFS('Committments Dump'!$R:$R,'Committments Dump'!$C:$C,'Category Table'!Y$2,'Committments Dump'!$B:$B,'Category Table'!$A18) | Z18: =SUMIFS('Committments Dump'!$R:$R,'Committments Dump'!$C:$C,'Category Table'!Z$2,'Committments Dump'!$B:$B,'Category Table'!$A18) | AA18: =SUMIFS('Committments Dump'!$S:$S,'Committments Dump'!$C:$C,'Category Table'!AA$2,'Committments Dump'!$B:$B,'Category Table'!$A18) | AB18: =SUMIFS('Committments Dump'!$S:$S,'Committments Dump'!$C:$C,'Category Table'!AB$2,'Committments Dump'!$B:$B,'Category Table'!$A18) | AC18: =SUMIFS('Committments Dump'!$S:$S,'Committments Dump'!$C:$C,'Category Table'!AC$2,'Committments Dump'!$B:$B,'Category Table'!$A18) | AD18: =U18+X18+AA18 | AE18: =V18+Y18+AB18 | AF18: =W18+Z18+AC18 | AG18: =R18+AD18 | AH18: =S18+AE18 | AI18: =T18+AF18 | AM18: =(O18-AG18)+AJ18 | AN18: =(P18-AH18)+AK18 | AO18: =(Q18-AI18)+AL18 | AP18: =IF(AM18>0, "Under",IF(AM18<0,"Over","")) | AQ18: =IF(AN18>0, "Under",IF(AN18<0,"Over","")) | AR18: =IF(AO18>0, "Under",IF(AO18<0,"Over",""))
A19: 0-4007 | B19: 0-4007-Mowing | C19: 0 | D19: 0 | E19: 0 | F19: 0 | G19: 0 | H19: 0 | I19: 0 | J19: 0 | K19: 0 | L19: 0 | M19: 0 | N19: 0 | O19: =L19+I19+F19+C19 | P19: =M19+J19+G19+D19 | Q19: =N19+K19+H19+E19 | R19: =SUMIFS('PO Log'!$E:$E,'PO Log'!$D:$D,'Category Table'!R$2,'PO Log'!$C:$C,'Category Table'!$A19) | S19: =SUMIFS('PO Log'!$E:$E,'PO Log'!$D:$D,'Category Table'!S$2,'PO Log'!$C:$C,'Category Table'!$A19) | T19: =SUMIFS('PO Log'!$E:$E,'PO Log'!$D:$D,'Category Table'!T$2,'PO Log'!$C:$C,'Category Table'!$A19) | U19: =SUMIFS('Committments Dump'!$Q:$Q,'Committments Dump'!$C:$C,'Category Table'!U$2,'Committments Dump'!$B:$B,'Category Table'!$A19) | V19: =SUMIFS('Committments Dump'!$Q:$Q,'Committments Dump'!$C:$C,'Category Table'!V$2,'Committments Dump'!$B:$B,'Category Table'!$A19) | W19: =SUMIFS('Committments Dump'!$Q:$Q,'Committments Dump'!$C:$C,'Category Table'!W$2,'Committments Dump'!$B:$B,'Category Table'!$A19) | X19: =SUMIFS('Committments Dump'!$R:$R,'Committments Dump'!$C:$C,'Category Table'!X$2,'Committments Dump'!$B:$B,'Category Table'!$A19) | Y19: =SUMIFS('Committments Dump'!$R:$R,'Committments Dump'!$C:$C,'Category Table'!Y$2,'Committments Dump'!$B:$B,'Category Table'!$A19) | Z19: =SUMIFS('Committments Dump'!$R:$R,'Committments Dump'!$C:$C,'Category Table'!Z$2,'Committments Dump'!$B:$B,'Category Table'!$A19) | AA19: =SUMIFS('Committments Dump'!$S:$S,'Committments Dump'!$C:$C,'Category Table'!AA$2,'Committments Dump'!$B:$B,'Category Table'!$A19) | AB19: =SUMIFS('Committments Dump'!$S:$S,'Committments Dump'!$C:$C,'Category Table'!AB$2,'Committments Dump'!$B:$B,'Category Table'!$A19) | AC19: =SUMIFS('Committments Dump'!$S:$S,'Committments Dump'!$C:$C,'Category Table'!AC$2,'Committments Dump'!$B:$B,'Category Table'!$A19) | AD19: =U19+X19+AA19 | AE19: =V19+Y19+AB19 | AF19: =W19+Z19+AC19 | AG19: =R19+AD19 | AH19: =S19+AE19 | AI19: =T19+AF19 | AM19: =(O19-AG19)+AJ19 | AN19: =(P19-AH19)+AK19 | AO19: =(Q19-AI19)+AL19 | AP19: =IF(AM19>0, "Under",IF(AM19<0,"Over","")) | AQ19: =IF(AN19>0, "Under",IF(AN19<0,"Over","")) | AR19: =IF(AO19>0, "Under",IF(AO19<0,"Over",""))
A20: 0-4008 | B20: 0-4008-Supplies | C20: 0 | D20: 108788 | E20: 0 | F20: 0 | G20: 2245561.2 | H20: 0 | I20: 0 | J20: 10749.05 | K20: 0 | L20: 0 | M20: 60149.43 | N20: 0 | O20: =L20+I20+F20+C20 | P20: =M20+J20+G20+D20 | Q20: =N20+K20+H20+E20 | R20: =SUMIFS('PO Log'!$E:$E,'PO Log'!$D:$D,'Category Table'!R$2,'PO Log'!$C:$C,'Category Table'!$A20) | S20: =SUMIFS('PO Log'!$E:$E,'PO Log'!$D:$D,'Category Table'!S$2,'PO Log'!$C:$C,'Category Table'!$A20) | T20: =SUMIFS('PO Log'!$E:$E,'PO Log'!$D:$D,'Category Table'!T$2,'PO Log'!$C:$C,'Category Table'!$A20) | U20: =SUMIFS('Committments Dump'!$Q:$Q,'Committments Dump'!$C:$C,'Category Table'!U$2,'Committments Dump'!$B:$B,'Category Table'!$A20) | V20: =SUMIFS('Committments Dump'!$Q:$Q,'Committments Dump'!$C:$C,'Category Table'!V$2,'Committments Dump'!$B:$B,'Category Table'!$A20) | W20: =SUMIFS('Committments Dump'!$Q:$Q,'Committments Dump'!$C:$C,'Category Table'!W$2,'Committments Dump'!$B:$B,'Category Table'!$A20) | X20: =SUMIFS('Committments Dump'!$R:$R,'Committments Dump'!$C:$C,'Category Table'!X$2,'Committments Dump'!$B:$B,'Category Table'!$A20) | Y20: =SUMIFS('Committments Dump'!$R:$R,'Committments Dump'!$C:$C,'Category Table'!Y$2,'Committments Dump'!$B:$B,'Category Table'!$A20) | Z20: =SUMIFS('Committments Dump'!$R:$R,'Committments Dump'!$C:$C,'Category Table'!Z$2,'Committments Dump'!$B:$B,'Category Table'!$A20) | AA20: =SUMIFS('Committments Dump'!$S:$S,'Committments Dump'!$C:$C,'Category Table'!AA$2,'Committments Dump'!$B:$B,'Category Table'!$A20) | AB20: =SUMIFS('Committments Dump'!$S:$S,'Committments Dump'!$C:$C,'Category Table'!AB$2,'Committments Dump'!$B:$B,'Category Table'!$A20) | AC20: =SUMIFS('Committments Dump'!$S:$S,'Committments Dump'!$C:$C,'Category Table'!AC$2,'Committments Dump'!$B:$B,'Category Table'!$A20) | AD20: =U20+X20+AA20 | AE20: =V20+Y20+AB20 | AF20: =W20+Z20+AC20 | AG20: =R20+AD20 | AH20: =S20+AE20 | AI20: =T20+AF20 | AM20: =(O20-AG20)+AJ20 | AN20: =(P20-AH20)+AK20 | AO20: =(Q20-AI20)+AL20 | AP20: =IF(AM20>0, "Under",IF(AM20<0,"Over","")) | AQ20: =IF(AN20>0, "Under",IF(AN20<0,"Over","")) | AR20: =IF(AO20>0, "Under",IF(AO20<0,"Over",""))
A21: 0-4010 | B21: 0-4010-FOG | C21: 0 | D21: 42925.37 | E21: 0 | F21: 0 | G21: 1855762.9 | H21: 0 | I21: 0 | J21: -63562.62 | K21: 0 | L21: 0 | M21: 0 | N21: 0 | O21: =L21+I21+F21+C21 | P21: =M21+J21+G21+D21 | Q21: =N21+K21+H21+E21 | R21: =SUMIFS('PO Log'!$E:$E,'PO Log'!$D:$D,'Category Table'!R$2,'PO Log'!$C:$C,'Category Table'!$A21) | S21: =SUMIFS('PO Log'!$E:$E,'PO Log'!$D:$D,'Category Table'!S$2,'PO Log'!$C:$C,'Category Table'!$A21) | T21: =SUMIFS('PO Log'!$E:$E,'PO Log'!$D:$D,'Category Table'!T$2,'PO Log'!$C:$C,'Category Table'!$A21) | U21: =SUMIFS('Committments Dump'!$Q:$Q,'Committments Dump'!$C:$C,'Category Table'!U$2,'Committments Dump'!$B:$B,'Category Table'!$A21) | V21: =SUMIFS('Committments Dump'!$Q:$Q,'Committments Dump'!$C:$C,'Category Table'!V$2,'Committments Dump'!$B:$B,'Category Table'!$A21) | W21: =SUMIFS('Committments Dump'!$Q:$Q,'Committments Dump'!$C:$C,'Category Table'!W$2,'Committments Dump'!$B:$B,'Category Table'!$A21) | X21: =SUMIFS('Committments Dump'!$R:$R,'Committments Dump'!$C:$C,'Category Table'!X$2,'Committments Dump'!$B:$B,'Category Table'!$A21) | Y21: =SUMIFS('Committments Dump'!$R:$R,'Committments Dump'!$C:$C,'Category Table'!Y$2,'Committments Dump'!$B:$B,'Category Table'!$A21) | Z21: =SUMIFS('Committments Dump'!$R:$R,'Committments Dump'!$C:$C,'Category Table'!Z$2,'Committments Dump'!$B:$B,'Category Table'!$A21) | AA21: =SUMIFS('Committments Dump'!$S:$S,'Committments Dump'!$C:$C,'Category Table'!AA$2,'Committments Dump'!$B:$B,'Category Table'!$A21) | AB21: =SUMIFS('Committments Dump'!$S:$S,'Committments Dump'!$C:$C,'Category Table'!AB$2,'Committments Dump'!$B:$B,'Category Table'!$A21) | AC21: =SUMIFS('Committments Dump'!$S:$S,'Committments Dump'!$C:$C,'Category Table'!AC$2,'Committments Dump'!$B:$B,'Category Table'!$A21) | AD21: =U21+X21+AA21 | AE21: =V21+Y21+AB21 | AF21: =W21+Z21+AC21 | AG21: =R21+AD21 | AH21: =S21+AE21 | AI21: =T21+AF21 | AM21: =(O21-AG21)+AJ21 | AN21: =(P21-AH21)+AK21 | AO21: =(Q21-AI21)+AL21 | AP21: =IF(AM21>0, "Under",IF(AM21<0,"Over","")) | AQ21: =IF(AN21>0, "Under",IF(AN21<0,"Over","")) | AR21: =IF(AO21>0, "Under",IF(AO21<0,"Over",""))
A22: 0-4013 | B22: 0-4013-Contingency | C22: 0 | D22: 0 | E22: 0 | F22: 4883701.6 | H22: 0 | I22: 0 | J22: 0 | K22: 0 | L22: 0 | M22: 0 | N22: 0 | O22: =L22+I22+F22+C22 | P22: =M22+J22+G22+D22 | Q22: =N22+K22+H22+E22 | R22: =SUMIFS('PO Log'!$E:$E,'PO Log'!$D:$D,'Category Table'!R$2,'PO Log'!$C:$C,'Category Table'!$A22) | S22: =SUMIFS('PO Log'!$E:$E,'PO Log'!$D:$D,'Category Table'!S$2,'PO Log'!$C:$C,'Category Table'!$A22) | T22: =SUMIFS('PO Log'!$E:$E,'PO Log'!$D:$D,'Category Table'!T$2,'PO Log'!$C:$C,'Category Table'!$A22) | U22: =SUMIFS('Committments Dump'!$Q:$Q,'Committments Dump'!$C:$C,'Category Table'!U$2,'Committments Dump'!$B:$B,'Category Table'!$A22) | V22: =SUMIFS('Committments Dump'!$Q:$Q,'Committments Dump'!$C:$C,'Category Table'!V$2,'Committments Dump'!$B:$B,'Category Table'!$A22) | W22: =SUMIFS('Committments Dump'!$Q:$Q,'Committments Dump'!$C:$C,'Category Table'!W$2,'Committments Dump'!$B:$B,'Category Table'!$A22) | X22: =SUMIFS('Committments Dump'!$R:$R,'Committments Dump'!$C:$C,'Category Table'!X$2,'Committments Dump'!$B:$B,'Category Table'!$A22) | Y22: =SUMIFS('Committments Dump'!$R:$R,'Committments Dump'!$C:$C,'Category Table'!Y$2,'Committments Dump'!$B:$B,'Category Table'!$A22) | Z22: =SUMIFS('Committments Dump'!$R:$R,'Committments Dump'!$C:$C,'Category Table'!Z$2,'Committments Dump'!$B:$B,'Category Table'!$A22) | AA22: =SUMIFS('Committments Dump'!$S:$S,'Committments Dump'!$C:$C,'Category Table'!AA$2,'Committments Dump'!$B:$B,'Category Table'!$A22) | AB22: =SUMIFS('Committments Dump'!$S:$S,'Committments Dump'!$C:$C,'Category Table'!AB$2,'Committments Dump'!$B:$B,'Category Table'!$A22) | AC22: =SUMIFS('Committments Dump'!$S:$S,'Committments Dump'!$C:$C,'Category Table'!AC$2,'Committments Dump'!$B:$B,'Category Table'!$A22) | AD22: =U22+X22+AA22 | AE22: =V22+Y22+AB22 | AF22: =W22+Z22+AC22 | AG22: =R22+AD22 | AH22: =S22+AE22 | AI22: =T22+AF22 | AM22: =(O22-AG22)+AJ22 | AN22: =(P22-AH22)+AK22 | AO22: =(Q22-AI22)+AL22 | AP22: =IF(AM22>0, "Under",IF(AM22<0,"Over","")) | AQ22: =IF(AN22>0, "Under",IF(AN22<0,"Over","")) | AR22: =IF(AO22>0, "Under",IF(AO22<0,"Over",""))
A23: 0-4013-01 | B23: 0-4013-01-LD's | C23: 0 | D23: 0 | E23: 0 | F23: 1800000 | G23: 0 | H23: 0 | I23: 0 | J23: 0 | K23: 0 | L23: 0 | M23: 0 | N23: 0 | O23: =L23+I23+F23+C23 | P23: =M23+J23+G23+D23 | Q23: =N23+K23+H23+E23 | R23: =SUMIFS('PO Log'!$E:$E,'PO Log'!$D:$D,'Category Table'!R$2,'PO Log'!$C:$C,'Category Table'!$A23) | S23: =SUMIFS('PO Log'!$E:$E,'PO Log'!$D:$D,'Category Table'!S$2,'PO Log'!$C:$C,'Category Table'!$A23) | T23: =SUMIFS('PO Log'!$E:$E,'PO Log'!$D:$D,'Category Table'!T$2,'PO Log'!$C:$C,'Category Table'!$A23) | U23: =SUMIFS('Committments Dump'!$Q:$Q,'Committments Dump'!$C:$C,'Category Table'!U$2,'Committments Dump'!$B:$B,'Category Table'!$A23) | V23: =SUMIFS('Committments Dump'!$Q:$Q,'Committments Dump'!$C:$C,'Category Table'!V$2,'Committments Dump'!$B:$B,'Category Table'!$A23) | W23: =SUMIFS('Committments Dump'!$Q:$Q,'Committments Dump'!$C:$C,'Category Table'!W$2,'Committments Dump'!$B:$B,'Category Table'!$A23) | X23: =SUMIFS('Committments Dump'!$R:$R,'Committments Dump'!$C:$C,'Category Table'!X$2,'Committments Dump'!$B:$B,'Category Table'!$A23) | Y23: =SUMIFS('Committments Dump'!$R:$R,'Committments Dump'!$C:$C,'Category Table'!Y$2,'Committments Dump'!$B:$B,'Category Table'!$A23) | Z23: =SUMIFS('Committments Dump'!$R:$R,'Committments Dump'!$C:$C,'Category Table'!Z$2,'Committments Dump'!$B:$B,'Category Table'!$A23) | AA23: =SUMIFS('Committments Dump'!$S:$S,'Committments Dump'!$C:$C,'Category Table'!AA$2,'Committments Dump'!$B:$B,'Category Table'!$A23) | AB23: =SUMIFS('Committments Dump'!$S:$S,'Committments Dump'!$C:$C,'Category Table'!AB$2,'Committments Dump'!$B:$B,'Category Table'!$A23) | AC23: =SUMIFS('Committments Dump'!$S:$S,'Committments Dump'!$C:$C,'Category Table'!AC$2,'Committments Dump'!$B:$B,'Category Table'!$A23) | AD23: =U23+X23+AA23 | AE23: =V23+Y23+AB23 | AF23: =W23+Z23+AC23 | AG23: =R23+AD23 | AH23: =S23+AE23 | AI23: =T23+AF23 | AM23: =(O23-AG23)+AJ23 | AN23: =(P23-AH23)+AK23 | AO23: =(Q23-AI23)+AL23 | AP23: =IF(AM23>0, "Under",IF(AM23<0,"Over","")) | AQ23: =IF(AN23>0, "Under",IF(AN23<0,"Over","")) | AR23: =IF(AO23>0, "Under",IF(AO23<0,"Over",""))
A24: 0-4013-02 | B24: 0-4013-02-Weather Cont. | C24: 0 | D24: 0 | E24: 0 | F24: 1386221 | G24: 0 | H24: 0 | I24: 0 | J24: 0 | K24: 0 | L24: 0 | M24: 0 | N24: 0 | O24: =L24+I24+F24+C24 | P24: =M24+J24+G24+D24 | Q24: =N24+K24+H24+E24 | R24: =SUMIFS('PO Log'!$E:$E,'PO Log'!$D:$D,'Category Table'!R$2,'PO Log'!$C:$C,'Category Table'!$A24) | S24: =SUMIFS('PO Log'!$E:$E,'PO Log'!$D:$D,'Category Table'!S$2,'PO Log'!$C:$C,'Category Table'!$A24) | T24: =SUMIFS('PO Log'!$E:$E,'PO Log'!$D:$D,'Category Table'!T$2,'PO Log'!$C:$C,'Category Table'!$A24) | U24: =SUMIFS('Committments Dump'!$Q:$Q,'Committments Dump'!$C:$C,'Category Table'!U$2,'Committments Dump'!$B:$B,'Category Table'!$A24) | V24: =SUMIFS('Committments Dump'!$Q:$Q,'Committments Dump'!$C:$C,'Category Table'!V$2,'Committments Dump'!$B:$B,'Category Table'!$A24) | W24: =SUMIFS('Committments Dump'!$Q:$Q,'Committments Dump'!$C:$C,'Category Table'!W$2,'Committments Dump'!$B:$B,'Category Table'!$A24) | X24: =SUMIFS('Committments Dump'!$R:$R,'Committments Dump'!$C:$C,'Category Table'!X$2,'Committments Dump'!$B:$B,'Category Table'!$A24) | Y24: =SUMIFS('Committments Dump'!$R:$R,'Committments Dump'!$C:$C,'Category Table'!Y$2,'Committments Dump'!$B:$B,'Category Table'!$A24) | Z24: =SUMIFS('Committments Dump'!$R:$R,'Committments Dump'!$C:$C,'Category Table'!Z$2,'Committments Dump'!$B:$B,'Category Table'!$A24) | AA24: =SUMIFS('Committments Dump'!$S:$S,'Committments Dump'!$C:$C,'Category Table'!AA$2,'Committments Dump'!$B:$B,'Category Table'!$A24) | AB24: =SUMIFS('Committments Dump'!$S:$S,'Committments Dump'!$C:$C,'Category Table'!AB$2,'Committments Dump'!$B:$B,'Category Table'!$A24) | AC24: =SUMIFS('Committments Dump'!$S:$S,'Committments Dump'!$C:$C,'Category Table'!AC$2,'Committments Dump'!$B:$B,'Category Table'!$A24) | AD24: =U24+X24+AA24 | AE24: =V24+Y24+AB24 | AF24: =W24+Z24+AC24 | AG24: =R24+AD24 | AH24: =S24+AE24 | AI24: =T24+AF24 | AM24: =(O24-AG24)+AJ24 | AN24: =(P24-AH24)+AK24 | AO24: =(Q24-AI24)+AL24 | AP24: =IF(AM24>0, "Under",IF(AM24<0,"Over","")) | AQ24: =IF(AN24>0, "Under",IF(AN24<0,"Over","")) | AR24: =IF(AO24>0, "Under",IF(AO24<0,"Over",""))
A25: 0-4015 | B25: 0-4015-Survey | C25: 28288.75 | D25: 956.01 | E25: 325.83 | F25: 466368.3 | G25: -144949.54 | H25: 0 | I25: 0 | J25: 0 | K25: 0 | L25: 0 | M25: 0 | N25: 0 | O25: =L25+I25+F25+C25 | P25: =M25+J25+G25+D25 | Q25: =N25+K25+H25+E25 | R25: =SUMIFS('PO Log'!$E:$E,'PO Log'!$D:$D,'Category Table'!R$2,'PO Log'!$C:$C,'Category Table'!$A25) | S25: =SUMIFS('PO Log'!$E:$E,'PO Log'!$D:$D,'Category Table'!S$2,'PO Log'!$C:$C,'Category Table'!$A25) | T25: =SUMIFS('PO Log'!$E:$E,'PO Log'!$D:$D,'Category Table'!T$2,'PO Log'!$C:$C,'Category Table'!$A25) | U25: =SUMIFS('Committments Dump'!$Q:$Q,'Committments Dump'!$C:$C,'Category Table'!U$2,'Committments Dump'!$B:$B,'Category Table'!$A25) | V25: =SUMIFS('Committments Dump'!$Q:$Q,'Committments Dump'!$C:$C,'Category Table'!V$2,'Committments Dump'!$B:$B,'Category Table'!$A25) | W25: =SUMIFS('Committments Dump'!$Q:$Q,'Committments Dump'!$C:$C,'Category Table'!W$2,'Committments Dump'!$B:$B,'Category Table'!$A25) | X25: =SUMIFS('Committments Dump'!$R:$R,'Committments Dump'!$C:$C,'Category Table'!X$2,'Committments Dump'!$B:$B,'Category Table'!$A25) | Y25: =SUMIFS('Committments Dump'!$R:$R,'Committments Dump'!$C:$C,'Category Table'!Y$2,'Committments Dump'!$B:$B,'Category Table'!$A25) | Z25: =SUMIFS('Committments Dump'!$R:$R,'Committments Dump'!$C:$C,'Category Table'!Z$2,'Committments Dump'!$B:$B,'Category Table'!$A25) | AA25: =SUMIFS('Committments Dump'!$S:$S,'Committments Dump'!$C:$C,'Category Table'!AA$2,'Committments Dump'!$B:$B,'Category Table'!$A25) | AB25: =SUMIFS('Committments Dump'!$S:$S,'Committments Dump'!$C:$C,'Category Table'!AB$2,'Committments Dump'!$B:$B,'Category Table'!$A25) | AC25: =SUMIFS('Committments Dump'!$S:$S,'Committments Dump'!$C:$C,'Category Table'!AC$2,'Committments Dump'!$B:$B,'Category Table'!$A25) | AD25: =U25+X25+AA25 | AE25: =V25+Y25+AB25 | AF25: =W25+Z25+AC25 | AG25: =R25+AD25 | AH25: =S25+AE25 | AI25: =T25+AF25 | AM25: =(O25-AG25)+AJ25 | AN25: =(P25-AH25)+AK25 | AO25: =(Q25-AI25)+AL25 | AP25: =IF(AM25>0, "Under",IF(AM25<0,"Over","")) | AQ25: =IF(AN25>0, "Under",IF(AN25<0,"Over","")) | AR25: =IF(AO25>0, "Under",IF(AO25<0,"Over",""))
A26: 0-4016 | B26: 0-4016-Permits | C26: 20024.36 | D26: 0 | E26: 0 | F26: 0 | G26: 0 | H26: 36554.39 | I26: 0 | J26: 0 | K26: 0 | L26: 43421.25 | M26: 0 | N26: 0 | O26: =L26+I26+F26+C26 | P26: =M26+J26+G26+D26 | Q26: =N26+K26+H26+E26 | R26: =SUMIFS('PO Log'!$E:$E,'PO Log'!$D:$D,'Category Table'!R$2,'PO Log'!$C:$C,'Category Table'!$A26) | S26: =SUMIFS('PO Log'!$E:$E,'PO Log'!$D:$D,'Category Table'!S$2,'PO Log'!$C:$C,'Category Table'!$A26) | T26: =SUMIFS('PO Log'!$E:$E,'PO Log'!$D:$D,'Category Table'!T$2,'PO Log'!$C:$C,'Category Table'!$A26) | U26: =SUMIFS('Committments Dump'!$Q:$Q,'Committments Dump'!$C:$C,'Category Table'!U$2,'Committments Dump'!$B:$B,'Category Table'!$A26) | V26: =SUMIFS('Committments Dump'!$Q:$Q,'Committments Dump'!$C:$C,'Category Table'!V$2,'Committments Dump'!$B:$B,'Category Table'!$A26) | W26: =SUMIFS('Committments Dump'!$Q:$Q,'Committments Dump'!$C:$C,'Category Table'!W$2,'Committments Dump'!$B:$B,'Category Table'!$A26) | X26: =SUMIFS('Committments Dump'!$R:$R,'Committments Dump'!$C:$C,'Category Table'!X$2,'Committments Dump'!$B:$B,'Category Table'!$A26) | Y26: =SUMIFS('Committments Dump'!$R:$R,'Committments Dump'!$C:$C,'Category Table'!Y$2,'Committments Dump'!$B:$B,'Category Table'!$A26) | Z26: =SUMIFS('Committments Dump'!$R:$R,'Committments Dump'!$C:$C,'Category Table'!Z$2,'Committments Dump'!$B:$B,'Category Table'!$A26) | AA26: =SUMIFS('Committments Dump'!$S:$S,'Committments Dump'!$C:$C,'Category Table'!AA$2,'Committments Dump'!$B:$B,'Category Table'!$A26) | AB26: =SUMIFS('Committments Dump'!$S:$S,'Committments Dump'!$C:$C,'Category Table'!AB$2,'Committments Dump'!$B:$B,'Category Table'!$A26) | AC26: =SUMIFS('Committments Dump'!$S:$S,'Committments Dump'!$C:$C,'Category Table'!AC$2,'Committments Dump'!$B:$B,'Category Table'!$A26) | AD26: =U26+X26+AA26 | AE26: =V26+Y26+AB26 | AF26: =W26+Z26+AC26 | AG26: =R26+AD26 | AH26: =S26+AE26 | AI26: =T26+AF26 | AM26: =(O26-AG26)+AJ26 | AN26: =(P26-AH26)+AK26 | AO26: =(Q26-AI26)+AL26 | AP26: =IF(AM26>0, "Under",IF(AM26<0,"Over","")) | AQ26: =IF(AN26>0, "Under",IF(AN26<0,"Over","")) | AR26: =IF(AO26>0, "Under",IF(AO26<0,"Over",""))
A27: 0-4017 | B27: 0-4017-Utility Locate | C27: 0 | D27: 849.86 | E27: 0 | F27: 2821.59 | G27: 0 | H27: 0 | I27: 0 | J27: 0 | K27: 0 | L27: 0 | M27: 21328.55 | N27: 0 | O27: =L27+I27+F27+C27 | P27: =M27+J27+G27+D27 | Q27: =N27+K27+H27+E27 | R27: =SUMIFS('PO Log'!$E:$E,'PO Log'!$D:$D,'Category Table'!R$2,'PO Log'!$C:$C,'Category Table'!$A27) | S27: =SUMIFS('PO Log'!$E:$E,'PO Log'!$D:$D,'Category Table'!S$2,'PO Log'!$C:$C,'Category Table'!$A27) | T27: =SUMIFS('PO Log'!$E:$E,'PO Log'!$D:$D,'Category Table'!T$2,'PO Log'!$C:$C,'Category Table'!$A27) | U27: =SUMIFS('Committments Dump'!$Q:$Q,'Committments Dump'!$C:$C,'Category Table'!U$2,'Committments Dump'!$B:$B,'Category Table'!$A27) | V27: =SUMIFS('Committments Dump'!$Q:$Q,'Committments Dump'!$C:$C,'Category Table'!V$2,'Committments Dump'!$B:$B,'Category Table'!$A27) | W27: =SUMIFS('Committments Dump'!$Q:$Q,'Committments Dump'!$C:$C,'Category Table'!W$2,'Committments Dump'!$B:$B,'Category Table'!$A27) | X27: =SUMIFS('Committments Dump'!$R:$R,'Committments Dump'!$C:$C,'Category Table'!X$2,'Committments Dump'!$B:$B,'Category Table'!$A27) | Y27: =SUMIFS('Committments Dump'!$R:$R,'Committments Dump'!$C:$C,'Category Table'!Y$2,'Committments Dump'!$B:$B,'Category Table'!$A27) | Z27: =SUMIFS('Committments Dump'!$R:$R,'Committments Dump'!$C:$C,'Category Table'!Z$2,'Committments Dump'!$B:$B,'Category Table'!$A27) | AA27: =SUMIFS('Committments Dump'!$S:$S,'Committments Dump'!$C:$C,'Category Table'!AA$2,'Committments Dump'!$B:$B,'Category Table'!$A27) | AB27: =SUMIFS('Committments Dump'!$S:$S,'Committments Dump'!$C:$C,'Category Table'!AB$2,'Committments Dump'!$B:$B,'Category Table'!$A27) | AC27: =SUMIFS('Committments Dump'!$S:$S,'Committments Dump'!$C:$C,'Category Table'!AC$2,'Committments Dump'!$B:$B,'Category Table'!$A27) | AD27: =U27+X27+AA27 | AE27: =V27+Y27+AB27 | AF27: =W27+Z27+AC27 | AG27: =R27+AD27 | AH27: =S27+AE27 | AI27: =T27+AF27 | AM27: =(O27-AG27)+AJ27 | AN27: =(P27-AH27)+AK27 | AO27: =(Q27-AI27)+AL27 | AP27: =IF(AM27>0, "Under",IF(AM27<0,"Over","")) | AQ27: =IF(AN27>0, "Under",IF(AN27<0,"Over","")) | AR27: =IF(AO27>0, "Under",IF(AO27<0,"Over",""))
A28: 0-4024 | B28: 0-4024-Engineering | C28: 1128965 | D28: 28340.55 | E28: 0 | F28: 1419040.4 | G28: 0 | H28: 0 | I28: 0 | J28: 0 | K28: 0 | L28: 223654.01 | M28: 0 | N28: 0 | O28: =L28+I28+F28+C28 | P28: =M28+J28+G28+D28 | Q28: =N28+K28+H28+E28 | R28: =SUMIFS('PO Log'!$E:$E,'PO Log'!$D:$D,'Category Table'!R$2,'PO Log'!$C:$C,'Category Table'!$A28) | S28: =SUMIFS('PO Log'!$E:$E,'PO Log'!$D:$D,'Category Table'!S$2,'PO Log'!$C:$C,'Category Table'!$A28) | T28: =SUMIFS('PO Log'!$E:$E,'PO Log'!$D:$D,'Category Table'!T$2,'PO Log'!$C:$C,'Category Table'!$A28) | U28: =SUMIFS('Committments Dump'!$Q:$Q,'Committments Dump'!$C:$C,'Category Table'!U$2,'Committments Dump'!$B:$B,'Category Table'!$A28) | V28: =SUMIFS('Committments Dump'!$Q:$Q,'Committments Dump'!$C:$C,'Category Table'!V$2,'Committments Dump'!$B:$B,'Category Table'!$A28) | W28: =SUMIFS('Committments Dump'!$Q:$Q,'Committments Dump'!$C:$C,'Category Table'!W$2,'Committments Dump'!$B:$B,'Category Table'!$A28) | X28: =SUMIFS('Committments Dump'!$R:$R,'Committments Dump'!$C:$C,'Category Table'!X$2,'Committments Dump'!$B:$B,'Category Table'!$A28) | Y28: =SUMIFS('Committments Dump'!$R:$R,'Committments Dump'!$C:$C,'Category Table'!Y$2,'Committments Dump'!$B:$B,'Category Table'!$A28) | Z28: =SUMIFS('Committments Dump'!$R:$R,'Committments Dump'!$C:$C,'Category Table'!Z$2,'Committments Dump'!$B:$B,'Category Table'!$A28) | AA28: =SUMIFS('Committments Dump'!$S:$S,'Committments Dump'!$C:$C,'Category Table'!AA$2,'Committments Dump'!$B:$B,'Category Table'!$A28) | AB28: =SUMIFS('Committments Dump'!$S:$S,'Committments Dump'!$C:$C,'Category Table'!AB$2,'Committments Dump'!$B:$B,'Category Table'!$A28) | AC28: =SUMIFS('Committments Dump'!$S:$S,'Committments Dump'!$C:$C,'Category Table'!AC$2,'Committments Dump'!$B:$B,'Category Table'!$A28) | AD28: =U28+X28+AA28 | AE28: =V28+Y28+AB28 | AF28: =W28+Z28+AC28 | AG28: =R28+AD28 | AH28: =S28+AE28 | AI28: =T28+AF28 | AM28: =(O28-AG28)+AJ28 | AN28: =(P28-AH28)+AK28 | AO28: =(Q28-AI28)+AL28 | AP28: =IF(AM28>0, "Under",IF(AM28<0,"Over","")) | AQ28: =IF(AN28>0, "Under",IF(AN28<0,"Over","")) | AR28: =IF(AO28>0, "Under",IF(AO28<0,"Over",""))
A29: 0-4029 | B29: 0-4029-ACS | C29: 0 | D29: 0 | E29: 0 | F29: 1680000 | G29: 0 | H29: 0 | I29: 0 | J29: 0 | K29: 0 | L29: 0 | M29: 0 | N29: 0 | O29: =L29+I29+F29+C29 | P29: =M29+J29+G29+D29 | Q29: =N29+K29+H29+E29 | R29: =SUMIFS('PO Log'!$E:$E,'PO Log'!$D:$D,'Category Table'!R$2,'PO Log'!$C:$C,'Category Table'!$A29) | S29: =SUMIFS('PO Log'!$E:$E,'PO Log'!$D:$D,'Category Table'!S$2,'PO Log'!$C:$C,'Category Table'!$A29) | T29: =SUMIFS('PO Log'!$E:$E,'PO Log'!$D:$D,'Category Table'!T$2,'PO Log'!$C:$C,'Category Table'!$A29) | U29: =SUMIFS('Committments Dump'!$Q:$Q,'Committments Dump'!$C:$C,'Category Table'!U$2,'Committments Dump'!$B:$B,'Category Table'!$A29) | V29: =SUMIFS('Committments Dump'!$Q:$Q,'Committments Dump'!$C:$C,'Category Table'!V$2,'Committments Dump'!$B:$B,'Category Table'!$A29) | W29: =SUMIFS('Committments Dump'!$Q:$Q,'Committments Dump'!$C:$C,'Category Table'!W$2,'Committments Dump'!$B:$B,'Category Table'!$A29) | X29: =SUMIFS('Committments Dump'!$R:$R,'Committments Dump'!$C:$C,'Category Table'!X$2,'Committments Dump'!$B:$B,'Category Table'!$A29) | Y29: =SUMIFS('Committments Dump'!$R:$R,'Committments Dump'!$C:$C,'Category Table'!Y$2,'Committments Dump'!$B:$B,'Category Table'!$A29) | Z29: =SUMIFS('Committments Dump'!$R:$R,'Committments Dump'!$C:$C,'Category Table'!Z$2,'Committments Dump'!$B:$B,'Category Table'!$A29) | AA29: =SUMIFS('Committments Dump'!$S:$S,'Committments Dump'!$C:$C,'Category Table'!AA$2,'Committments Dump'!$B:$B,'Category Table'!$A29) | AB29: =SUMIFS('Committments Dump'!$S:$S,'Committments Dump'!$C:$C,'Category Table'!AB$2,'Committments Dump'!$B:$B,'Category Table'!$A29) | AC29: =SUMIFS('Committments Dump'!$S:$S,'Committments Dump'!$C:$C,'Category Table'!AC$2,'Committments Dump'!$B:$B,'Category Table'!$A29) | AD29: =U29+X29+AA29 | AE29: =V29+Y29+AB29 | AF29: =W29+Z29+AC29 | AG29: =R29+AD29 | AH29: =S29+AE29 | AI29: =T29+AF29 | AM29: =(O29-AG29)+AJ29 | AN29: =(P29-AH29)+AK29 | AO29: =(Q29-AI29)+AL29 | AP29: =IF(AM29>0, "Under",IF(AM29<0,"Over","")) | AQ29: =IF(AN29>0, "Under",IF(AN29<0,"Over","")) | AR29: =IF(AO29>0, "Under",IF(AO29<0,"Over",""))
